Workbook

Sheet Leia-me
A2: CORRELAÇÃO LEGISLATIVA CFTA
B3: Assembleias legislativas, Congresso Nacional e marco normativo do técnico agrícola
A5: Produzido por | B5: Belli Relações Governamentais para o Conselho Federal dos Técnicos Agrícolas
A6: Posição | B6: 12 de agosto de 2026
A8: O QUE É ESTA PLANILHA
B9: Reúne, em uma única base, as proposições legislativas que podem afetar as competências do técnico agrícola — nas assembleias legislativas e no Congresso Nacional — e as correlaciona com o marco normativo que sustenta a atuação do Conselho.
B10: A correlação é feita por eixo de competência. Quando uma proposição estadual e uma federal tocam o mesmo eixo, elas disputam o mesmo espaço normativo e devem ser lidas em conjunto — é isso que a aba Correlação por eixo mostra.
A12: ABAS
A13: Correlação por eixo | B13: Os 12 eixos de competência, as normas que os sustentam e a contagem de matérias correlacionadas em cada esfera.
A14: Assembleias | B14: Proposições estaduais selecionadas, com casa de origem, autoria, eixo, prioridade e motivo do interesse.
A15: Novas federais | B15: Matérias federais identificadas na varredura de agosto que ainda não constavam da carteira monitorada — candidatas a entrar no radar.
A16: Federais monitoradas | B16: As 56 matérias já cadastradas na plataforma Governor, com situação processual e eixo de competência.
A17: Marco normativo | B17: As normas correlacionadas, por eixo.
A18: Triagem | B18: O funil completo: quantos registros entraram, quantos foram descartados e por quê.
A20: COMO FOI FEITA A TRIAGEM
A21: Exclusão formal | B21: Foram descartadas moções, homenagens, votos de pesar e congratulação, denominações de logradouros e equipamentos, datas comemorativas, títulos de cidadão, sessões solenes, requerimentos de informação e pedidos de licença — matérias sem conteúdo legislativo material.
A22: Classificação | B22: Cada ementa foi confrontada com os termos de cada eixo de competência. O peso de cada termo reflete o grau de especificidade: 'técnico agrícola' pesa mais que 'assistência técnica', que pesa mais que 'agricultura familiar'.
A23: Corte de aderência | B23: Matérias com pontuação somada abaixo de 10 foram descartadas por aderência fraca. O corte foi auditado: nenhuma matéria de alta relevância ficou abaixo dele.
A24: Prioridade | B24: Muito alta a partir de 24 pontos, ou 18 pontos com dois ou mais eixos; alta a partir de 17; médio-alta a partir de 12; média abaixo disso. Na base consolidada de abril, a prioridade original atribuída na triagem foi preservada.
A26: LIMITES DECLARADOS
A27: Recorte temporal | B27: A varredura de 11/08/2026 cobre apenas proposições apresentadas em 2026. Matérias anteriores ainda em tramitação nas assembleias não estão nesse recorte — permanecem na base consolidada de abril, que cobre anos anteriores.
A28: Resoluções do CFTA | B28: O marco normativo aqui correlacionado reúne leis, decretos e instruções normativas federais. As resoluções próprias do Conselho ainda não foram incorporadas — quando a relação for fornecida, entram como uma quarta camada da correlação, sem alterar a estrutura.
A29: Validação pendente | B29: A seleção é uma proposta técnica. A entrada de cada matéria no radar permanente depende de validação do CFTA.

Sheet Correlação por eixo
A1: Eixo | B1: Competência | C1: O que abrange | D1: Marco normativo correlacionado | E1: Federais monitoradas | F1: Proposições estaduais | G1: Novas federais | H1: Total de matérias | I1: Casas legislativas
A2: E1 | B2: Exercício profissional e responsabilidade técnica | C2: Atribuições do técnico agrícola, emissão de ART/TRT e habilitação legal para assinar projetos, laudos e responsabilidades técnicas. | D2: Lei nº 5.524/1968 · Decreto nº 90.922/1985 · Lei nº 13.639/2018 · Lei nº 6.496/1977 · Lei nº 5.194/1966 | E2: =COUNTIF('Federais monitoradas'!$N:$N,"*|"&$A2&"|*") -> 17 | F2: =COUNTIF(Assembleias!$R:$R,"*|"&$A2&"|*") -> 9 | G2: =COUNTIF('Novas federais'!$R:$R,"*|"&$A2&"|*") -> 2 | H2: =SUM(E2:G2) -> 28 | I2: 7
A3: E2 | B3: Assistência técnica e extensão rural | C3: Política de ATER, composição de equipes técnicas e cobertura de assistência ao produtor rural. | D3: Lei nº 12.188/2010 · Lei nº 8.171/1991 | E3: =COUNTIF('Federais monitoradas'!$N:$N,"*|"&$A3&"|*") -> 3 | F3: =COUNTIF(Assembleias!$R:$R,"*|"&$A3&"|*") -> 82 | G3: =COUNTIF('Novas federais'!$R:$R,"*|"&$A3&"|*") -> 14 | H3: =SUM(E3:G3) -> 99 | I3: 10
A4: E3 | B4: Defesa agropecuária, inspeção e sanidade | C4: Inspeção industrial e sanitária, defesa sanitária vegetal e animal e fiscalização de produtos de origem animal e vegetal. | D4: Lei nº 1.283/1950 · Lei nº 9.712/1998 · Lei nº 7.889/1989 | E4: =COUNTIF('Federais monitoradas'!$N:$N,"*|"&$A4&"|*") -> 4 | F4: =COUNTIF(Assembleias!$R:$R,"*|"&$A4&"|*") -> 9 | G4: =COUNTIF('Novas federais'!$R:$R,"*|"&$A4&"|*") -> 9 | H4: =SUM(E4:G4) -> 22 | I4: 8
A5: E4 | B5: Agrotóxicos, bioinsumos e fertilizantes | C5: Registro, aplicação, fiscalização e receituário de agrotóxicos, bioinsumos, fertilizantes e corretivos, inclusive aplicação aeroagrícola. | D5: Lei nº 14.785/2023 · Decreto nº 12.858/2026 · IN MAPA nº 53/2013 | E5: =COUNTIF('Federais monitoradas'!$N:$N,"*|"&$A5&"|*") -> 4 | F5: =COUNTIF(Assembleias!$R:$R,"*|"&$A5&"|*") -> 4 | G5: =COUNTIF('Novas federais'!$R:$R,"*|"&$A5&"|*") -> 10 | H5: =SUM(E5:G5) -> 18 | I5: 3
A6: E5 | B6: Agroindústria e produção artesanal | C6: Agroindústria familiar, produtos artesanais, certificação e regularização de pequenas unidades de processamento. | D6: Lei nº 8.171/1991 · Lei nº 13.680/2018 · Lei nº 8.918/1994 | E6: =COUNTIF('Federais monitoradas'!$N:$N,"*|"&$A6&"|*") -> 5 | F6: =COUNTIF(Assembleias!$R:$R,"*|"&$A6&"|*") -> 6 | G6: =COUNTIF('Novas federais'!$R:$R,"*|"&$A6&"|*") -> 2 | H6: =SUM(E6:G6) -> 13 | I6: 4
A7: E6 | B7: Sementes, mudas e material propagativo | C7: Produção, comércio, multiplicação e fiscalização de sementes e mudas, incluindo cultivares locais e crioulas. | D7: Lei nº 10.711/2003 · Lei nº 9.456/1997 | E7: =COUNTIF('Federais monitoradas'!$N:$N,"*|"&$A7&"|*") -> 4 | F7: =COUNTIF(Assembleias!$R:$R,"*|"&$A7&"|*") -> 72 | G7: =COUNTIF('Novas federais'!$R:$R,"*|"&$A7&"|*") -> 1 | H7: =SUM(E7:G7) -> 77 | I7: 4
A8: E7 | B8: Regularização fundiária e georreferenciamento | C8: Reurb, registros públicos, cadastro rural, georreferenciamento e levantamentos planialtimétricos. | D8: Lei nº 13.465/2017 · Lei nº 6.015/1973 · Lei nº 11.952/2009 · Lei nº 10.267/2001 | E8: =COUNTIF('Federais monitoradas'!$N:$N,"*|"&$A8&"|*") -> 11 | F8: =COUNTIF(Assembleias!$R:$R,"*|"&$A8&"|*") -> 6 | G8: =COUNTIF('Novas federais'!$R:$R,"*|"&$A8&"|*") -> 3 | H8: =SUM(E8:G8) -> 20 | I8: 4
A9: E8 | B9: Meio ambiente aplicado à atividade rural | C9: Licenciamento ambiental, áreas de preservação, recursos hídricos e passivos ambientais com exigência de responsável técnico. | D9: Lei nº 12.651/2012 · Lei nº 6.938/1981 · Lei nº 9.433/1997 | E9: =COUNTIF('Federais monitoradas'!$N:$N,"*|"&$A9&"|*") -> 6 | F9: =COUNTIF(Assembleias!$R:$R,"*|"&$A9&"|*") -> 20 | G9: =COUNTIF('Novas federais'!$R:$R,"*|"&$A9&"|*") -> 8 | H9: =SUM(E9:G9) -> 34 | I9: 6
A10: E9 | B10: Formação, ensino técnico e qualificação profissional | C10: Educação profissional agrícola, escolas técnicas, estágio e programas de qualificação. | D10: Lei nº 9.394/1996 · Lei nº 11.892/2008 · Lei nº 11.788/2008 | E10: =COUNTIF('Federais monitoradas'!$N:$N,"*|"&$A10&"|*") -> 4 | F10: =COUNTIF(Assembleias!$R:$R,"*|"&$A10&"|*") -> 2 | G10: =COUNTIF('Novas federais'!$R:$R,"*|"&$A10&"|*") -> 5 | H10: =SUM(E10:G10) -> 11 | I10: 2
A11: E10 | B11: Conselhos profissionais, anuidades e fiscalização | C11: Regime jurídico, arrecadação, anuidades e poder de fiscalização dos conselhos de profissões regulamentadas. | D11: Lei nº 13.639/2018 · Lei nº 12.514/2011 · Lei nº 10.741/2003 | E11: =COUNTIF('Federais monitoradas'!$N:$N,"*|"&$A11&"|*") -> 11 | F11: =COUNTIF(Assembleias!$R:$R,"*|"&$A11&"|*") -> 0 | G11: =COUNTIF('Novas federais'!$R:$R,"*|"&$A11&"|*") -> 2 | H11: =SUM(E11:G11) -> 13 | I11: 0
A12: E11 | B12: Crédito rural, tributação e política agrícola | C12: Crédito, seguro rural, ITR e instrumentos de política agrícola que exigem laudo, projeto ou responsável técnico. | D12: Lei nº 8.171/1991 · Lei nº 9.393/1996 · Lei nº 8.629/1993 | E12: =COUNTIF('Federais monitoradas'!$N:$N,"*|"&$A12&"|*") -> 4 | F12: =COUNTIF(Assembleias!$R:$R,"*|"&$A12&"|*") -> 17 | G12: =COUNTIF('Novas federais'!$R:$R,"*|"&$A12&"|*") -> 39 | H12: =SUM(E12:G12) -> 60 | I12: 5
A13: E12 | B13: Produção animal, aquicultura e cadeias específicas | C13: Pecuária, aquicultura, apicultura e demais cadeias em que o técnico agrícola atua como responsável técnico. | D13: Lei nº 11.959/2009 · Lei nº 5.517/1968 | E13: =COUNTIF('Federais monitoradas'!$N:$N,"*|"&$A13&"|*") -> 4 | F13: =COUNTIF(Assembleias!$R:$R,"*|"&$A13&"|*") -> 119 | G13: =COUNTIF('Novas federais'!$R:$R,"*|"&$A13&"|*") -> 30 | H13: =SUM(E13:G13) -> 153 | I13: 13
B14: Total de vínculos eixo-matéria | E14: =SUM(E2:E13) -> 77 | F14: =SUM(F2:F13) -> 346 | G14: =SUM(G2:G13) -> 125 | H14: =SUM(H2:H13) -> 548
B16: Uma matéria pode integrar mais de um eixo; por isso a soma de vínculos supera o total de matérias selecionadas.

Sheet Assembleias
A1: Identificador | B1: Casa legislativa | C1: Tipo | D1: Autoria | E1: Partido | F1: UF | G1: Ano | H1: Data | I1: Eixo principal | J1: Eixos | K1: Prioridade | L1: Aderência | M1: Categoria | N1: Motivo do interesse para o CFTA | O1: Ação sugerida | P1: Base de origem | Q1: Ementa | R1: Chave
A2: IND 16341/2026 | B2: ALERO (RO) | C2: Indicação | D2: Cláudia de Jesus | G2: 2026 | I2: E2 | J2: E2, E1 | K2: Muito alta | L2: 42 | M2: Assistência técnica, extensão e carreira pública | N2: Afeta assistência técnica, extensão rural, formação técnica ou estrutura de carreira ligada ao setor agropecuário. | O2: Monitorar tramitação e avaliar posicionamento institucional. | P2: Consolidada · abr/2026 | Q2: INDICA ao Poder Executivo Estadual, extensivo à Casa Civil e à Entidade Autárquica de Assistência Técnica e Extensão Rural do Estado de Rondônia — EMATER, a necessidade de disponibilização de técnico agrícola ou agrônomo para o município de Pimenteiras do Oeste/RO. | R2: |E2|E1|
A3: IND 5620/2026 | B3: ALES (ES) | C3: Indicação | D3: João Coser | G3: 2026 | H3: 2026-03-30 | I3: E2 | J3: E2, E1, E12 | K3: Muito alta | L3: 42 | M3: Assistência técnica, extensão e carreira pública | N3: Afeta assistência técnica, extensão rural, formação técnica ou estrutura de carreira ligada ao setor agropecuário. | O3: Monitorar tramitação e avaliar posicionamento institucional. | P3: Consolidada · abr/2026 | Q3: O Deputado João Coser requer seja encaminhada ao Governador do Estado do Espírito Santo a seguinte Indicação Parlamentar: "Considerando as propostas de recomposição salarial de carreira no âmbito do Instituto Capixaba de Pesquisa, Assistência Técnica e Extensão Rural (Incaper) e da Secretaria de Estado de Gestão e Recursos Humanos (Seger), solicita-se: (i) Seja assegurada a manutenção da equiparação remuneratória dos servidores integrantes da carreira de Técnico de Suporte em Desenvolvimento Rural em relação aos Técnicos em Desenvolvimento Rural (técnicos em agropecuária); (ii) Alternativamente, seja analisada, de forma concreta, a possibilidade de enquadramento da carreira de Técnico de Suporte em Desenvolvimento Rural na carreira de Técnico em Desenvolvimento Rural, como medida de justiça funcional e de garantia de tratamento isonômico entre servidores que exercem funções de natureza equivalente". | R3: |E2|E1|E12|
A4: RQN 16855/2026 | B4: ALEMG (MG) | C4: Requerimento | D4: Comissão de Cultura | G4: 2026 | H4: 2026-03-24 | I4: E2 | J4: E2, E5, E12 | K4: Muito alta | L4: 40 | M4: Assistência técnica, extensão e carreira pública | N4: Afeta assistência técnica, extensão rural, formação técnica ou estrutura de carreira ligada ao setor agropecuário. | O4: Monitorar tramitação e avaliar posicionamento institucional. | P4: Consolidada · abr/2026 | Q4: Requer seja encaminhado à Empresa de Assistência Técnica e Extensão Rural do Estado de Minas Gerais, ao Instituto Mineiro de Agropecuária e ao Ministério da Agricultura e Pecuária pedido de providências para que, em parceria, realizem pesquisa para mapeamento da produção e dos produtores de cachaça artesanal nas comunidades quilombolas do Estado, com vistas ao desenvolvimento de políticas de proteção e certificação específicas para esse público. | R4: |E2|E5|E12|
A5: IND 15020/2026 | B5: ALEPE (PE) | C5: Indicação | D5: Romero Sales Filho | G5: 2026 | H5: 2026-02-03 | I5: E2 | J5: E2, E6, E12 | K5: Muito alta | L5: 37 | M5: Assistência técnica, extensão e carreira pública | N5: Afeta assistência técnica, extensão rural, formação técnica ou estrutura de carreira ligada ao setor agropecuário. | O5: Monitorar tramitação e avaliar posicionamento institucional. | P5: Consolidada · abr/2026 | Q5: Indicamos à Mesa, ouvido o Plenário e cumpridas as formalidades regimentais, que seja encaminhado apelo à Excelentíssima Senhora Raquel Lyra, Governadora do Estado de Pernambuco; ao Ilustríssimo Sr. Cícero Moraes Secretário de Desenvolvimento Agrário, Agricultura, Pecuária e Pesca; e ao Ilustríssimo Sr. Miguel Duque, Presidente Instituto Agronômico de Pernambuco (IPA), no sentido de viabilizar a inclusão do município de São José da Coroa Grande nos programas e ações previstas pelo órgão para o biênio 2025–2026, a saber: o Programa Terra Plantar; a Recuperação de Estradas Vicinais; o fortalecimento da estrutura da Prestação de Serviço de Assistência Técnica e Extensão Rural – ATER; e o Programa de Distribuição de Sementes – Safra 2025. | R5: |E2|E6|E12|
A6: IND 15485/2026 | B6: ALERO (RO) | C6: Indicação | D6: Cláudia de Jesus | G6: 2026 | I6: E2 | J6: E2, E5 | K6: Muito alta | L6: 37 | M6: Assistência técnica, extensão e carreira pública | N6: Afeta assistência técnica, extensão rural, formação técnica ou estrutura de carreira ligada ao setor agropecuário. | O6: Monitorar tramitação e avaliar posicionamento institucional. | P6: Consolidada · abr/2026 | Q6: INDICA ao Poder Executivo Estadual, extensivo à Casa Civil, à Secretaria de Estado da Agricultura – SEAGRI, ao Conselho de Desenvolvimento do Agronegócio Leite do Estado de Rondônia – CONDALRON, à Secretaria de Estado do Desenvolvimento Econômico – SEDEC e à Entidade Autárquica de Assistência Técnica e Extensão Rural do Estado de Rondônia – EMATER, a necessidade de adoção de providências para que, nas compras governamentais de leite e de derivados lácteos, seja priorizado o fornecimento por agroindústrias e cooperativas sediadas no Estado de Rondônia. | R6: |E2|E5|
A7: REQ 2428/2026 | B7: ALRN (RN) | C7: REQ | D7: DEPUTADA DIVANEIDE BASÍLIO | G7: 2026 | H7: 15/07/2026 | I7: E2 | J7: E2, E12 | K7: Muito alta | L7: 33 | P7: Varredura · ago/2026 | Q7: requer que seja encaminhado expediente à Secretaria de Estado do Desenvolvimento Rural e da Agricultura Familiar - SEDRAF, à Empresa de Assistência Técnica e Extensão Rural do Rio Grande do Norte - EMATER-RN, à Empresa de Pesquisa Agropecuária do Rio Grande do Norte - EMPARN e ao Instituto de Desenvolvimento Sustentável e Meio Ambiente do Rio Grande do Norte - IDEMA, solicitando o fortalecimento das iniciativas de bioeconomia e da cadeia produtiva das plantas medicinais. | R7: |E2|E12|
A8: IND 4799/2026 | B8: ALES (ES) | C8: Indicação | D8: Zé Preto | G8: 2026 | H8: 2026-03-25 | I8: E5 | J8: E5, E12, E11, E2 | K8: Alta | L8: 32 | M8: Crédito rural, seguro e financiamento | N8: Pode alterar instrumentos de crédito ou financiamento relevantes para produtores rurais e para a assistência técnica. | O8: Monitorar tramitação e mapear impacto para produtores e assistência técnica. | P8: Consolidada · abr/2026 | Q8: Indico, por intermédio da Secretaria de Estado da Agricultura, Abastecimento, Aquicultura e Pesca – SEAG, e dos demais órgãos competentes, a adoção de providências para a criação e estruturação de um Fundo Estadual de Apoio à Agricultura Familiar, destinado ao fortalecimento da produção rural, ao incentivo à agroindustrialização, à ampliação da comercialização dos produtos da agricultura familiar e ao desenvolvimento sustentável do meio rural no Estado do Espírito Santo. | R8: |E5|E12|E11|E2|
A9: IND 4800/2026 | B9: ALES (ES) | C9: Indicação | D9: Zé Preto | G9: 2026 | H9: 2026-03-25 | I9: E5 | J9: E5, E12, E11, E2 | K9: Médio-alta | L9: 32 | M9: Produção agropecuária e cadeias produtivas | N9: Incide sobre produção agropecuária, cadeias produtivas ou atividades de interesse direto das modalidades registradas no CFTA. | O9: Acompanhar tramitação e classificar impacto setorial para o CFTA. | P9: Consolidada · abr/2026 | Q9: Indico, por intermédio da Secretaria de Estado da Agricultura, Abastecimento, Aquicultura e Pesca – SEAG, e dos demais órgãos competentes, a adoção de providências para a implantação e fortalecimento de ações estaduais de incentivo à agroindústria familiar no Estado do Espírito Santo, com foco na regularização, capacitação, apoio técnico e ampliação da comercialização dos produtos oriundos da agricultura familiar capixaba. | R9: |E5|E12|E11|E2|
A10: IND 4552/2026 | B10: ALES (ES) | C10: Indicação | D10: Zé Preto | G10: 2026 | H10: 2026-03-23 | I10: E5 | J10: E5, E12, E11, E2 | K10: Médio-alta | L10: 32 | M10: Produção agropecuária e cadeias produtivas | N10: Incide sobre produção agropecuária, cadeias produtivas ou atividades de interesse direto das modalidades registradas no CFTA. | O10: Acompanhar tramitação e classificar impacto setorial para o CFTA. | P10: Consolidada · abr/2026 | Q10: Indica por meio da Secretaria de Estado da Agricultura, Abastecimento, Aquicultura e Pesca – SEAG, a implantação de programa estadual de incentivo à agroindustrialização da agricultura familiar no Município de Alfredo Chaves. | R10: |E5|E12|E11|E2|
A11: RQN 16853/2026 | B11: ALEMG (MG) | C11: Requerimento | D11: Comissão de Cultura | G11: 2026 | H11: 2026-03-24 | I11: E2 | J11: E2, E12 | K11: Muito alta | L11: 30 | M11: Assistência técnica, extensão e carreira pública | N11: Afeta assistência técnica, extensão rural, formação técnica ou estrutura de carreira ligada ao setor agropecuário. | O11: Monitorar tramitação e avaliar posicionamento institucional. | P11: Consolidada · abr/2026 | Q11: Requer seja encaminhado à Empresa de Assistência Técnica e Extensão Rural do Estado de Minas Gerais e ao Instituto Mineiro de Agropecuária pedido de providências para a criação de canal de comunicação específico para atendimento de produtores de cachaça de comunidades quilombolas, respeitando-se a cultura e os saberes tradicionais dessas comunidades. | R11: |E2|E12|
A12: RQN 16854/2026 | B12: ALEMG (MG) | C12: Requerimento | D12: Comissão de Cultura | G12: 2026 | H12: 2026-03-24 | I12: E2 | J12: E2, E12 | K12: Muito alta | L12: 30 | M12: Assistência técnica, extensão e carreira pública | N12: Afeta assistência técnica, extensão rural, formação técnica ou estrutura de carreira ligada ao setor agropecuário. | O12: Monitorar tramitação e avaliar posicionamento institucional. | P12: Consolidada · abr/2026 | Q12: Requer seja encaminhado à Empresa de Assistência Técnica e Extensão Rural do Estado de Minas Gerais e ao Instituto Mineiro de Agropecuária pedido de providências para a criação de campanhas de divulgação dos serviços de apoio técnico ofertados por essas entidades aos fabricantes de cachaça e outros produtos artesanais das comunidades quilombolas e indígenas e de outras comunidades tradicionais. | R12: |E2|E12|
A13: IND 16623/2026 | B13: ALEPE (PE) | C13: IND | D13: Nino de Enoque | E13: PL | F13: PE | G13: 2026 | H13: 04/08/2026 | I13: E6 | J13: E6, E7, E12 | K13: Muito alta | L13: 30 | P13: Varredura · ago/2026 | Q13: Indicamos à Mesa, ouvido o Plenário e cumpridas as formalidades regimentais, que seja feito um apelo à Excelentíssima Senhora Governadora do Estado de Pernambuco, Raquel Teixeira Lyra Lucena, e ao Excelentíssimo Senhor Secretário de Desenvolvimento Agrário, Agricultura, Pecuária e Pesca de Pernambuco, Cícero Vicente Marinho Xavier de Moraes, para que sejam adotadas as providências necessárias à regularização fundiária das áreas ocupadas pelas famílias assentadas e ao apoio à estruturação de banco de sementes comunitário, em benefício das comunidades rurais do município de Pesqueira – PE | R13: |E6|E7|E12|
A14: REQ 27591/2026 | B14: ALPB (PB) | C14: Requerimento | D14: — | G14: 2026 | I14: E2 | J14: E2, E7, E12 | K14: Muito alta | L14: 30 | M14: Assistência técnica, extensão e carreira pública | N14: Afeta assistência técnica, extensão rural, formação técnica ou estrutura de carreira ligada ao setor agropecuário. | O14: Monitorar tramitação e avaliar posicionamento institucional. | P14: Consolidada · abr/2026 | Q14: REQUEIRO que seja encaminhado apelo à Empresa Paraibana de Pesquisa, Extensão Rural e Regularização Fundiária – EMPAER, à Secretaria de Estado do Desenvolvimento da Agropecuária e da Pesca da Paraíba e ao Excelentíssimo Senhor Governador do Estado da Paraíba, solicitando a ampliação da assistência técnica rural com foco na agroecologia nos municípios do Brejo Paraibano. | R14: |E2|E7|E12|
A15: IND 15337/2026 | B15: ALERO (RO) | C15: Indicação | D15: Cláudia de Jesus | G15: 2026 | I15: E2 | J15: E2 | K15: Muito alta | L15: 28 | M15: Assistência técnica, extensão e carreira pública | N15: Afeta assistência técnica, extensão rural, formação técnica ou estrutura de carreira ligada ao setor agropecuário. | O15: Monitorar tramitação e avaliar posicionamento institucional. | P15: Consolidada · abr/2026 | Q15: INDICA ao Poder Executivo do Estado de Rondônia, com cópias à Casa Civil, à Secretaria de Estado da Agricultura – SEAGRI e à Entidade Autárquica de Assistência Técnica e Extensão Rural do Estado de Rondônia – EMATER-RO, a necessidade de adoção de providências administrativas visando à contratação ou disponibilização de especialista em produção de cacau, com atuação direcionada às propriedades da agricultura familiar do município de Candeias do Jamari, bem como à orientação técnica para prevenção, monitoramento e manejo da monilíase do cacaueiro.. | R15: |E2|
A16: IND 15484/2026 | B16: ALERO (RO) | C16: Indicação | D16: Cláudia de Jesus | G16: 2026 | I16: E2 | J16: E2 | K16: Muito alta | L16: 25 | M16: Assistência técnica, extensão e carreira pública | N16: Afeta assistência técnica, extensão rural, formação técnica ou estrutura de carreira ligada ao setor agropecuário. | O16: Monitorar tramitação e avaliar posicionamento institucional. | P16: Consolidada · abr/2026 | Q16: INDICA ao Poder Executivo Estadual, extensivo à Casa Civil, à Secretaria de Estado da Agricultura – SEAGRI, ao Conselho de Desenvolvimento do Agronegócio Leite do Estado de Rondônia – CONDALRON, à Secretaria de Estado do Desenvolvimento Econômico – SEDEC, à Secretaria de Estado de Finanças – SEFIN, à Procuradoria-Geral do Estado de Rondônia – PGE e à Entidade Autárquica de Assistência Técnica e Extensão Rural do Estado de Rondônia – EMATER, a necessidade de adoção, em caráter de máxima urgência, de providências técnicas, administrativas e jurídicas visando à decretação de estado de calamidade pública na cadeia produtiva do leite no Estado de Rondônia, como medida excepcional de proteção econômica, social e produtiva. | R16: |E2|
A17: IND 15649/2026 | B17: ALERO (RO) | C17: Indicação | D17: Pedro Fernandes | G17: 2026 | I17: E2 | J17: E2 | K17: Muito alta | L17: 25 | M17: Assistência técnica, extensão e carreira pública | N17: Afeta assistência técnica, extensão rural, formação técnica ou estrutura de carreira ligada ao setor agropecuário. | O17: Monitorar tramitação e avaliar posicionamento institucional. | P17: Consolidada · abr/2026 | Q17: INDICA ao Poder Executivo Estadual, extensivo à Secretaria de Estado da Agricultura — SEAGRI, ao Conselho de Desenvolvimento do Agronegócio Leite do Estado de Rondônia — CONDALRON, à Secretaria de Estado do Desenvolvimento Econômico — SEDEC, à Secretaria de Estado de Finanças — SEFIN, e à Entidade Autárquica de Assistência Técnica e Extensão Rural do Estado de Rondônia — EMATER, a necessidade urgente de decretação de Estado de Calamidade Pública Estadual na cadeia produtiva do leite no Estado de Rondônia, em razão do baixo preço do leite pago aos produtores. | R17: |E2|
A18: REQ 3547/2026 | B18: ALERO (RO) | C18: Requerimento | D18: Coletiva | G18: 2026 | I18: E2 | J18: E2 | K18: Muito alta | L18: 25 | M18: Assistência técnica, extensão e carreira pública | N18: Afeta assistência técnica, extensão rural, formação técnica ou estrutura de carreira ligada ao setor agropecuário. | O18: Monitorar tramitação e avaliar posicionamento institucional. | P18: Consolidada · abr/2026 | Q18: Requer ao Poder Executivo Estadual, extensivo à Casa Civil, à Secretaria de Estado da Agricultura - SEAGRI, ao Conselho de Desenvolvimento do Agronegócio Leite do Estado de Rondônia - CONDALRON, à Secretaria de Estado do Desenvolvimento Econômico - SEDEC, à Secretaria de Estado de Finanças - SEFIN, à Procuradoria-Geral do Estado de Rondônia - PGE e à Entidade Autárquica de Assistência Técnica e Extensão Rural do Estado de Rondônia - EMATER, que adotem, em caráter de máxima urgência, as providências técnicas, administrativas e jurídicas necessárias à decretação de estado de calamidade pública na cadeia produtiva do leite no Estado de Rondônia, como medida excepcional de proteção econômica, social e produtiva. | R18: |E2|
A19: REQ 28020/2026 | B19: ALPB (PB) | C19: Requerimento | D19: — | G19: 2026 | I19: E11 | J19: E11, E2, E12 | K19: Muito alta | L19: 25 | M19: Crédito rural, seguro e financiamento | N19: Pode alterar instrumentos de crédito ou financiamento relevantes para produtores rurais e para a assistência técnica. | O19: Monitorar tramitação e mapear impacto para produtores e assistência técnica. | P19: Consolidada · abr/2026 | Q19: Requeiro, na forma regimental e após ouvido o Plenário, que seja encaminhado expediente ao Governador do Estado da Paraíba, Excelentíssimo Senhor João Azevêdo Lins, bem como à Secretaria de Estado do Desenvolvimento da Agropecuária e da Pesca, solicitando a ampliação de programas de incentivo à agricultura familiar, garantindo assistência técnica, acesso ao crédito rural, apoio logístico e políticas de comercialização da produção agrícola. | R19: |E11|E2|E12|
A20: PL 70/2026 | B20: ALEAM (AM) | C20: Projeto de lei | D20: Cristiano D’Angelo | G20: 2026 | I20: E3 | J20: E3, E4 | K20: Média | L20: 24 | M20: Agrotóxicos, fiscalização e biossegurança | N20: Relaciona-se à fiscalização, biossegurança, fitossanidade e execução técnica em ambiente regulado. | O20: Priorizar monitoramento e avaliar nota técnica regulatória. | P20: Consolidada · abr/2026 | Q20: REVOGA a LEI Nº 6.173, DE 29 DE DEZEMBRO DE 2022 que dispõe sobre as Taxas dos Serviços de Defesa Animal e Vegetal, Inspeção Animal, Agrotóxicos, Insumos Veterinários, Organismos Aquáticos, Taxa de Defesa Animal, Taxa de Defesa Sanitária e Taxa de Indenização, no Estado do Amazonas, e dá outras providências. | R20: |E3|E4|
A21: REQ 218/2026 | B21: ALMT (MT) | C21: Requerimento | D21: Gilberto Cattani | G21: 2026 | I21: E3 | J21: E3, E12 | K21: Muito alta | L21: 23 | M21: Agrotóxicos, fiscalização e biossegurança | N21: Relaciona-se à fiscalização, biossegurança, fitossanidade e execução técnica em ambiente regulado. | O21: Priorizar monitoramento e avaliar nota técnica regulatória. | P21: Consolidada · abr/2026 | Q21: REQUER AO PRESIDENTE DO INSTITUTO DE DEFESA AGROPECUÁRIA DO ESTADO DE MATO GROSSO – INDEA/MT INFORMAÇÕES E DOCUMENTOS ACERCA DA APURAÇÃO DE DENÚNCIA DE SUPOSTO ABATE CLANDESTINO DE OVINOS COM COMERCIALIZAÇÃO NO MUNICÍPIO DE LUCAS DO RIO VERDE - MT. | R21: |E3|E12|
A22: IND 756/2026 | B22: ALEAC (AC) | C22: IND | D22: Afonso Fernandes | E22: SD | F22: AC | G22: 2026 | H22: 04/08/2026 | I22: E3 | J22: E3, E12 | K22: Alta | L22: 17 | P22: Varredura · ago/2026 | Q22: Indico à Mesa Diretora, com fulcro no art. 169 da Resolução nº 86/1990, Regimento Interno da Assembleia Legislativa do Estado do Acre, que seja encaminhado expediente à Excelentíssima Senhora Mailza Assis Cameli, Governadora do Estado do Acre, com cópia à Secretaria de Estado de Agricultura - SEAGRI, à Secretaria de Estado de Planejamento - SEPLAN e ao Instituto de Defesa Agropecuária e Florestal do Acre - IDAF/AC, solicitando a realização de estudo de viabilidade e a estruturação do Projeto-Piloto Frio a Bordo, destinado a testar soluções de conservação pós-captura do pescado artesanal entre a captura e o desembarque, com eventual execução material a partir do exercício de 2027, observadas as exigências técnicas, sanitárias, ambientais, jurídicas, orçamentárias, eleitorais e de segurança da navegação. | R22: |E3|E12|
A23: IND 16427/2026 | B23: ALERO (RO) | C23: Indicação | D23: CIRONE DEIRÓ, ALEX REDANO | G23: 2026 | I23: E3 | J23: E3, E12 | K23: Muito alta | L23: 17 | M23: Agrotóxicos, fiscalização e biossegurança | N23: Relaciona-se à fiscalização, biossegurança, fitossanidade e execução técnica em ambiente regulado. | O23: Priorizar monitoramento e avaliar nota técnica regulatória. | P23: Consolidada · abr/2026 | Q23: INDICA ao Poder Executivo do Estado de Rondônia, com cópias à Casa Civil e a Agência de Defesa Sanitária Agrosilvopastoril do Estado de Rondônia - IDARON a adoção de providências visando à alteração da Lei Complementar Estadual nº 665, de 21 de maio de 2012, para adequação da sistemática de cálculo do Adicional de Desempenho da Defesa Agropecuária. | R23: |E3|E12|
A24: MGOV 27/2026 | B24: ALERR (RR) | C24: Proposição | D24: — | G24: 2026 | I24: E3 | J24: E3, E12 | K24: Muito alta | L24: 17 | M24: Agrotóxicos, fiscalização e biossegurança | N24: Relaciona-se à fiscalização, biossegurança, fitossanidade e execução técnica em ambiente regulado. | O24: Priorizar monitoramento e avaliar nota técnica regulatória. | P24: Consolidada · abr/2026 | Q24: Encaminha Projeto de Lei que "Altera a Lei nº 644, de 8 de abril de 2008, que dispõe sobre a criação da Agência de Defesa Agropecuária, e dá outras providências". | R24: |E3|E12|
A25: PL 58/2026 | B25: ALERR (RR) | C25: Projeto de lei | D25: — | G25: 2026 | I25: E3 | J25: E3, E12 | K25: Muito alta | L25: 17 | M25: Agrotóxicos, fiscalização e biossegurança | N25: Relaciona-se à fiscalização, biossegurança, fitossanidade e execução técnica em ambiente regulado. | O25: Priorizar monitoramento e avaliar nota técnica regulatória. | P25: Consolidada · abr/2026 | Q25: Altera a Lei nº 644, de 8 de abril de 2008 que dispõe sobre a criação da Agência de Defesa Agropecuária, e dá outras providências. | R25: |E3|E12|
A26: ORAC 17547/2026 | B26: ALES (ES) | C26: ORAC | D26: Adilson Espindula | E26: PP | F26: ES | G26: 2026 | H26: 04/08/2026 | I26: E12 | J26: E12, E11 | K26: Alta | L26: 17 | P26: Varredura · ago/2026 | Q26: Encaminho, na forma do art. 67, XVI do Regimento Interno desta Casa de Leis, o Relatório Mensal dos trabalhos da Comissão de Agricultura, de Silvicultura, de Aquicultura e Pesca, de Abastecimento, e de Reforma Agrária, referente o mês de JULHO/2026. | R26: |E12|E11|
A27: IND 17323/2026 | B27: ALES (ES) | C27: IND | D27: Adilson Espindula | E27: PP | F27: ES | G27: 2026 | H27: 03/08/2026 | I27: E12 | J27: E12, E11 | K27: Alta | L27: 17 | P27: Varredura · ago/2026 | Q27: I N D I C A Ç Ã O, para solicitar ao Governo do Estado do Espírito Santo, por meio da Secretaria de Estado da Agricultura, Abastecimento, Aquicultura e Pesca – SEAG, a realização de estudos técnicos e a execução das obras de duplicação da Estrada Rodolfo Nicolau Douro, no Município de Marechal Floriano/ES. | R27: |E12|E11|
A28: IND 17273/2026 | B28: ALES (ES) | C28: IND | D28: Coronel Weliton | E28: DC | F28: ES | G28: 2026 | H28: 30/07/2026 | I28: E12 | J28: E12, E11 | K28: Alta | L28: 17 | P28: Varredura · ago/2026 | Q28: O Deputado abaixo assinado, no uso de suas atribuições legais e regimentais, requer a Vossa Excelência, com fundamento nos artigos 141, inciso VIII e 174 do Regimento Interno da Assembleia Legislativa do Estado do Espírito Santo, que seja encaminhada ao EXCELENTÍSSIMO SENHOR GOVERNADOR DO ESTADO DO ESPÍRITO SANTO, por intermédio da Secretaria de Estado da Agricultura, Abastecimento, Aquicultura e Pesca, a INDICAÇÃO PARLAMENTAR da seguinte matéria: PAVIMENTAÇÃO COM BLOCOS INTERTRAVADOS OU APLICAÇÃO DE REVSOL NAS MARGENS DA RODOVIA (ES-185) EM FRENTE AOS EMPREENDIMENTOS DE GALPÕES, SITUADOS NA SAÍDA DA CIDADE DE IBITIRAMA/ES EM DIREÇÃO Á COMUNIDADE DE SÃO FRANCISCO. | R28: |E12|E11|
A29: REQ 130/2026 | B29: ALETO (TO) | C29: Requerimento | D29: WISTON GOMES | G29: 2026 | H29: 2026-02-24 | I29: E3 | J29: E3, E12 | K29: Muito alta | L29: 17 | M29: Agrotóxicos, fiscalização e biossegurança | N29: Relaciona-se à fiscalização, biossegurança, fitossanidade e execução técnica em ambiente regulado. | O29: Priorizar monitoramento e avaliar nota técnica regulatória. | P29: Consolidada · abr/2026 | Q29: Requer o envio de expediente ao Senhor Governador do Estado do Tocantins, com cópia à Agência de Defesa Agropecuária – ADAPEC para solicitar a Reforma do prédio onde funciona a Barreira fixa da ADAPEC no município de Pau D’arco. | R29: |E3|E12|
A30: REQ 28367/2026 | B30: ALPB (PB) | C30: Requerimento | D30: — | G30: 2026 | I30: E3 | J30: E3, E12 | K30: Muito alta | L30: 17 | M30: Agrotóxicos, fiscalização e biossegurança | N30: Relaciona-se à fiscalização, biossegurança, fitossanidade e execução técnica em ambiente regulado. | O30: Priorizar monitoramento e avaliar nota técnica regulatória. | P30: Consolidada · abr/2026 | Q30: Requerimento e apelo ao Excelentíssimo Senhor Governador do Estado da Paraíba, com cópia à Secretaria de Estado do Desenvolvimento da Agropecuária e da Pesca- SEDAP, à Secretaria de Estado da Administração e à Casa Civil, solicitando o enquadramento no quadro funcional da SEDAP, dos médicos veterinários aprovados no Concurso Público regido pelo Edital nº 02/2006- CPS/SEAD, bem como daqueles admitidos antes da Constituição Federal de 1988, além da inclusão desses profissionais nos Projetos de Lei encaminhados a esta Casa Legislativa que tratam da criação da Agência de Defesa Agropecuária do Estado da Paraíba (ADAP-PB) e da instituição do Plano de Cargos, Carreira e Remuneração da área. | R30: |E3|E12|
A31: IND 15738/2026 | B31: ALEPE (PE) | C31: Indicação | D31: Álvaro Porto | G31: 2026 | H31: 2026-03-19 | I31: E6 | J31: E6, E12, E2 | K31: Alta | L31: 15 | M31: Produção agropecuária e cadeias produtivas | N31: Incide sobre produção agropecuária, cadeias produtivas ou atividades de interesse direto das modalidades registradas no CFTA. | O31: Acompanhar tramitação e classificar impacto setorial para o CFTA. | P31: Consolidada · abr/2026 | Q31: Indicamos à Mesa, ouvido o Plenário e cumpridas as formalidades regimentais, que seja enviado um veemente apelo à Excelentíssima Sra. Governadora do Estado de Pernambuco, Raquel Lyra, ao Excelentíssimo Sr. Secretário de Desenvolvimento Agrário, Agricultura, Pecuária e Pesca do Estado de Pernambuco, Cícero Moraes, e ao Ilustríssimo Sr. Presidente do Instituto de Pesquisas Agronômicas de Pernambuco, Miguel Duque, no sentido de promoverem a distribuição de sementes aos agricultores da agricultura familiar do Município de Vertentes. | R31: |E6|E12|E2|
A32: IND 14981/2026 | B32: ALEPE (PE) | C32: Indicação | D32: Romero Sales Filho | G32: 2026 | H32: 2026-02-03 | I32: E6 | J32: E6, E12, E2 | K32: Alta | L32: 15 | M32: Produção agropecuária e cadeias produtivas | N32: Incide sobre produção agropecuária, cadeias produtivas ou atividades de interesse direto das modalidades registradas no CFTA. | O32: Acompanhar tramitação e classificar impacto setorial para o CFTA. | P32: Consolidada · abr/2026 | Q32: Indicamos à Mesa, ouvido o Plenário e cumpridas as formalidades regimentais, que seja encaminhado apelo à Excelentíssima Senhora Raquel Lyra, Governadora do Estado de Pernambuco, ao Ilustríssimo Senhor Cícero Moraes, Secretário de Desenvolvimento Agrário, Agricultura, Pecuária e Pesca do Estado de Pernambuco, e ao Ilustríssimo Senhor Miguel Arcanjo Ferraz Duque, Diretor-Presidente do Instituto Agronômico de Pernambuco – IPA, no sentido de viabilizar a aquisição de sementes para compor o Banco Municipal de Sementes da Agricultura Familiar no município de Tamandaré, por meio do Programa Sementes Crioulas. | R32: |E6|E12|E2|
A33: REQ 4816/2026 | B33: ALEPE (PE) | C33: Requerimento | D33: Romero Albuquerque | G33: 2026 | H33: 2026-03-03 | I33: E8 | J33: E8 | K33: Médio-alta | L33: 15 | M33: Produção agropecuária e cadeias produtivas | N33: Incide sobre produção agropecuária, cadeias produtivas ou atividades de interesse direto das modalidades registradas no CFTA. | O33: Acompanhar tramitação e classificar impacto setorial para o CFTA. | P33: Consolidada · abr/2026 | Q33: Requeremos à Mesa, nos termos do art. 246, inciso I, c/c art. 244, §1º, ambos da Resolução nº 1.891/2023 (Regimento Interno da Assembleia Legislativa do Estado de Pernambuco), que seja encaminhado Pedido de Informações ao Exmo. Sr. Túlio Frederico Tenório Vilaça Rodrigues, Secretário da Casa Civil do Estado de Pernambuco, acerca da implantação de plantas de produção de hidrogênio verde (H2V) e seus derivados, como o e-metanol, no âmbito do Complexo Industrial Portuário de Suape e da recém-criada Zona de Processamento de Exportação (ZPE). I – INFORMAÇÕES GERAIS SOBRE OS PROJETOS Considerando as informações públicas sobre a existência de, pelo menos, dois projetos em curso (European Energy e GoVerde Holding) , solicitamos: Relação completa e formal de todos os projetos de produção de hidrogênio verde (H2V) e derivados (como e-metanol e combustível sustentável de aviação - SAF) que estejam em qualquer estágio de negociação, aprovação ou implantação no âmbito do Complexo de Suape e/ou da ZPE. Para cada um dos projetos identificados (incluindo, mas não se limitando, aos da European Energy e GoVerde Holding), especificar: 2.1. Nome da empresa ou consórcio responsável e seu controle societário. 2.2. Estágio atual do projeto (protocolo de intenções, contrato de arrendamento assinado, licenciamento prévio obtido, licença de instalação, obras iniciadas, operação). 2.3. Produto final a ser gerado (ex: hidrogênio verde, e-metanol, SAF) e capacidade produtiva estimada (em toneladas/ano ou m³/dia). 2.4. Valor total do investimento previsto por projeto e a origem dos capitais (nacional/estrangeiro). 2.5. Área (em hectares) concedida para cada empreendimento e valor do contrato de arrendamento. 2.6. Cronograma atualizado com prazo estimado para início das obras e para o início da operação comercial (considerando as projeções para 2026, 2027 e 2028) . II – INCENTIVOS, CONTRAPARTIDAS E INFRAESTRUTURA DO CLUSTER Tendo em vista a criação do "Cluster Suape para Combustíveis de Baixo Carbono" e os investimentos previstos em infraestrutura compartilhada , questionamos: Detalhar todos os incentivos fiscais, creditícios, fundiários ou de infraestrutura concedidos ou em negociação para viabilizar os empreendimentos de H2V, especificando por projeto: 3.1. Tipo de incentivo concedido. 3.2. Base legal que autoriza a concessão do benefício. 3.3. Valor estimado do benefício fiscal ou financeiro, quando aplicável. 3.4. Prazo de vigência dos incentivos. 3.5. Contrapartidas exigidas das empresas (geração de empregos, investimentos mínimos, índice de conteúdo local, metas ambientais e de descarbonização). Informar se os projetos estão vinculados aos benefícios da Zona de Processamento de Exportação (ZPE) de Suape e quais as vantagens competitivas específicas oferecidas por este regime . Detalhar o plano de investimentos públicos e compartilhados para a estruturação do "Cluster Suape", no valor estimado de R$ 1,2 bilhão , incluindo: 5.1. Cronograma físico-financeiro das obras de infraestrutura (rede de dutos, tancagens, adequações portuárias, sistemas energéticos e hídricos). 5.2. Fontes dos recursos (estaduais, federais, parcerias público-privadas) e a parcela a ser custeada pelo setor privado. 5.3. Modelo de gestão e acesso compartilhado a essa infraestrutura pelas empresas do cluster. III – LICENCIAMENTO E IMPACTO AMBIENTAL Considerando a Licença Prévia (LP) já emitida para um dos empreendimentos , solicitamos: Para cada projeto em andamento, informar: 6.1. Situação atual do licenciamento ambiental (Licença Prévia - LP, Licença de Instalação - LI, ou Licença de Operação - LO). 6.2. Órgão responsável pelo licenciamento (CPRH ou IBAMA). 6.3. Exigência e, em caso positivo, existência de Estudo de Impacto Ambiental e Relatório de Impacto ao Meio Ambiente (EIA/RIMA) para cada planta. 6.4. Medidas de mitigação e compensação ambiental previstas, inclusive as relacionadas à captação de água e emissões. 6.5. Demanda estimada de recursos hídricos (consumo de água) e a matriz energética que será utilizada para a produção de hidrogênio verde, assegurando sua efetiva origem renovável. Informar se há uma avaliação ambiental estratégica para o cluster como um todo, considerando o efeito cumulativo dos múltiplos empreendimentos na região. IV – FINANCIAMENTO, PARCERIAS E INSERÇÃO EM POLÍTICAS PÚBLICAS Considerando as linhas de crédito federais e a agenda de eventos sobre o tema , perguntamos: Informar se há participação ou pleito junto a instituições financeiras públicas ou privadas para financiamento dos projetos, inclusive eventual financiamento do Banco Nacional de Desenvolvimento Econômico e Social (BNDES), Finep, ou de organismos internacionais. Esclarecer se os projetos estão formalmente inseridos na Estratégia Pernambucana para o Hidrogênio Verde e em políticas estruturantes como o Plano Pernambucano de Mudança Econômico-Ecológica (PerMeie) e a Política Estadual de Mudanças Climáticas. Informar sobre parcerias para pesquisa, desenvolvimento e inovação, como o "TecHub de Transição Energética" mencionado em parceria com o SENAI-PE, detalhando seu estágio de implementação e fontes de financiamento . V – IMPACTO SOCIOECONÔMICO E MÃO DE OBRA Para o conjunto dos projetos do cluster, informar a estimativa atualizada: 11.1. Número de empregos diretos e indiretos a serem gerados, discriminados por fase (implantação e operação). 11.2. Programas de capacitação e qualificação de mão de obra local vinculados aos projetos, com públicos-alvo e parcerias (ex: com o SENAI, IPA e universidades estaduais - UPE, UFRPE) . 11.3. Impacto estimado na arrecadação estadual e municipal (ICMS, ISS, etc.) com a maturação dos projetos, contrapondo com os incentivos fiscais eventualmente concedidos. | R33: |E8|
A34: IND 590/2026 | B34: ALMT (MT) | C34: Indicação | D34: Chico Guarnieri | G34: 2026 | I34: E6 | J34: E6, E12, E2 | K34: Alta | L34: 15 | M34: Produção agropecuária e cadeias produtivas | N34: Incide sobre produção agropecuária, cadeias produtivas ou atividades de interesse direto das modalidades registradas no CFTA. | O34: Acompanhar tramitação e classificar impacto setorial para o CFTA. | P34: Consolidada · abr/2026 | Q34: INDICO AO EXCELENTÍSSIMO SENHOR GOVERNADOR DO ESTADO, COM CÓPIA À SECRETARIA DE ESTADO DE AGRICULTURA FAMILIAR DE MATO GROSSO – SEAF/MT, A NECESSIDADE DE DESTINAÇÃO DE RECURSOS PARA A CONSTRUÇÃO DE UM BARRACÃO EQUIPADO COM CÂMARA FRIA PARA ARMAZENAMENTO E ESTOCAGEM DE SEMENTES, DESTINADO À COOPERATIVA AGROPECUÁRIA DO POVO INDÍGENA (COOPIPARÉSI), NO MUNICÍPIO DE CAMPO NOVO DO PARECIS/MT. | R34: |E6|E12|E2|
A35: REQ 28218/2026 | B35: ALPB (PB) | C35: Requerimento | D35: — | G35: 2026 | I35: E11 | J35: E11, E2 | K35: Muito alta | L35: 15 | M35: Crédito rural, seguro e financiamento | N35: Pode alterar instrumentos de crédito ou financiamento relevantes para produtores rurais e para a assistência técnica. | O35: Monitorar tramitação e mapear impacto para produtores e assistência técnica. | P35: Consolidada · abr/2026 | Q35: Requeiro, na forma regimental, que seja encaminhado APELO ao Governo do Estado da Paraíba, por meio dos órgãos competentes, no sentido de adotar políticas públicas de incentivo à agricultura familiar no município de Camalaú/PB, com a ampliação de programas de apoio técnico, distribuição de insumos agrícolas e acesso a crédito rural. | R35: |E11|E2|
A36: REQ 28369/2026 | B36: ALPB (PB) | C36: Requerimento | D36: — | G36: 2026 | I36: E11 | J36: E11, E2 | K36: Muito alta | L36: 15 | M36: Crédito rural, seguro e financiamento | N36: Pode alterar instrumentos de crédito ou financiamento relevantes para produtores rurais e para a assistência técnica. | O36: Monitorar tramitação e mapear impacto para produtores e assistência técnica. | P36: Consolidada · abr/2026 | Q36: Requeiro, na forma regimental, que seja encaminhado APELO ao Governo do Estado da Paraíba, por meio dos órgãos competentes, no sentido de adotar políticas públicas de incentivo à agricultura familiar no município de Massaranduba/PB, com a ampliação de programas de apoio técnico, distribuição de insumos agrícolas e acesso a crédito rural. | R36: |E11|E2|
A37: REQ 28571/2026 | B37: ALPB (PB) | C37: Requerimento | D37: — | G37: 2026 | I37: E11 | J37: E11, E2 | K37: Muito alta | L37: 15 | M37: Crédito rural, seguro e financiamento | N37: Pode alterar instrumentos de crédito ou financiamento relevantes para produtores rurais e para a assistência técnica. | O37: Monitorar tramitação e mapear impacto para produtores e assistência técnica. | P37: Consolidada · abr/2026 | Q37: Requeiro, na forma regimental, que seja encaminhado APELO ao Governo do Estado da Paraíba, por meio dos órgãos competentes, no sentido de adotar políticas públicas de incentivo à agricultura familiar no município de Ouro Velho/PB, com a ampliação de programas de apoio técnico, distribuição de insumos agrícolas e acesso a crédito rural. | R37: |E11|E2|
A38: REQ 28728/2026 | B38: ALPB (PB) | C38: Requerimento | D38: — | G38: 2026 | I38: E11 | J38: E11, E2 | K38: Muito alta | L38: 15 | M38: Crédito rural, seguro e financiamento | N38: Pode alterar instrumentos de crédito ou financiamento relevantes para produtores rurais e para a assistência técnica. | O38: Monitorar tramitação e mapear impacto para produtores e assistência técnica. | P38: Consolidada · abr/2026 | Q38: Requeiro, na forma regimental, que seja encaminhado APELO ao Governo do Estado da Paraíba, por meio dos órgãos competentes, no sentido de adotar políticas públicas de incentivo à agricultura familiar no município de São Miguel de Taipu/PB, com a ampliação de programas de apoio técnico, distribuição de insumos agrícolas e acesso a crédito rural. | R38: |E11|E2|
A39: REQ 28756/2026 | B39: ALPB (PB) | C39: Requerimento | D39: — | G39: 2026 | I39: E11 | J39: E11, E2 | K39: Muito alta | L39: 15 | M39: Crédito rural, seguro e financiamento | N39: Pode alterar instrumentos de crédito ou financiamento relevantes para produtores rurais e para a assistência técnica. | O39: Monitorar tramitação e mapear impacto para produtores e assistência técnica. | P39: Consolidada · abr/2026 | Q39: Requeiro, na forma regimental, que seja encaminhado APELO ao Governo do Estado da Paraíba, por meio dos órgãos competentes, no sentido de adotar políticas públicas de incentivo à agricultura familiar no município de Alagoa Nova/PB, com a ampliação de programas de apoio técnico, distribuição de insumos agrícolas e acesso a crédito rural. | R39: |E11|E2|
A40: REQ 28073/2026 | B40: ALPB (PB) | C40: Requerimento | D40: — | G40: 2026 | I40: E6 | J40: E6, E12, E2 | K40: Alta | L40: 15 | M40: Produção agropecuária e cadeias produtivas | N40: Incide sobre produção agropecuária, cadeias produtivas ou atividades de interesse direto das modalidades registradas no CFTA. | O40: Acompanhar tramitação e classificar impacto setorial para o CFTA. | P40: Consolidada · abr/2026 | Q40: REQUEIRO, a Vossa Excelência, nos termos do art. 112 do Regimento Interno desta Casa, que seja oficiada manifestação de apelo ao Senhor Rafael Lopes de Oliveira, Secretário Executivo da Agropecuária, para ampliação do programa de distribuição de sementes selecionadas (feijão, milho, sorgo) no Município de Alagoa Grande-PB, como reforço para o pequeno e médio produtor rural da agricultura familiar. | R40: |E6|E12|E2|
...

Sheet Novas federais
A1: Identificador | B1: Casa legislativa | C1: Tipo | D1: Autoria | E1: Partido | F1: UF | G1: Ano | H1: Data | I1: Eixo principal | J1: Eixos | K1: Prioridade | L1: Aderência | M1: Categoria | N1: Motivo do interesse para o CFTA | O1: Ação sugerida | P1: Base de origem | Q1: Ementa | R1: Chave
A2: PL 4517/2026 | B2: Câmara dos Deputados | C2: PL | D2: — | G2: 2026 | H2: 17/07/2026 | I2: E5 | J2: E5, E12, E2 | K2: Muito alta | L2: 31 | P2: Varredura · ago/2026 | Q2: Institui o Programa Nacional de Miniagroindústrias Comunitárias – PROMIC, destinado ao fortalecimento do beneficiamento local da produção comunitária, da agricultura familiar, da pesca artesanal, do extrativismo e da sociobiodiversidade, com foco na agregação de valor, geração de renda e desenvolvimento regional sustentável. | R2: |E5|E12|E2|
A3: PL 4297/2026 | B3: Câmara dos Deputados | C3: PL | D3: — | G3: 2026 | H3: 17/07/2026 | I3: E2 | J3: E2 | K3: Muito alta | L3: 28 | P3: Varredura · ago/2026 | Q3: Institui a Política Nacional de Fortalecimento Econômico e Proteção Territorial das Comunidades Quilombolas; altera a Lei nº 12.188, de 11 de janeiro de 2010, para fortalecer o atendimento prioritário às comunidades remanescentes de quilombos no âmbito da Política Nacional de Assistência Técnica e Extensão Rural para a Agricultura Familiar e Reforma Agrária; e estabelece diretrizes para inclusão produtiva, infraestrutura, conectividade e segurança territorial. | R3: |E2|
A4: PL 4738/2026 | B4: Câmara dos Deputados | C4: PL | D4: — | G4: 2026 | H4: 21/07/2026 | I4: E2 | J4: E2 | K4: Muito alta | L4: 28 | P4: Varredura · ago/2026 | Q4: Altera o art. 4º da Lei n° 12.188, de 11 de janeiro de 2010, para incluir objetivo na Política Nacional de Assistência Técnica e Extensão Rural para a Agricultura Familiar e Reforma Agrária (Pnater) voltado ao fomento da autonomia econômica e produtiva de mulheres negras agricultoras familiares, mulheres quilombolas e mulheres integrantes de povos e comunidades tradicionais. | R4: |E2|
A5: PL 104/2026 | B5: Câmara dos Deputados | C5: Projeto de lei | D5: — | G5: 2026 | H5: 2026-02-02 | I5: E7 | J5: E7, E11 | K5: Média | L5: 24 | M5: Crédito rural, seguro e financiamento | N5: Pode alterar instrumentos de crédito ou financiamento relevantes para produtores rurais e para a assistência técnica. | O5: Monitorar tramitação e mapear impacto para produtores e assistência técnica. | P5: Consolidada · abr/2026 | Q5: Altera a Lei nº 13.465, de 11 de julho de 2017, para instituir Certidão Provisória de Regularização Fundiária Rural – CPRF para fins de acesso a crédito rural nos casos que especifica. | R5: |E7|E11|
A6: PL 742/2026 | B6: Câmara dos Deputados | C6: Projeto de lei | D6: — | G6: 2026 | H6: 2026-02-25 | I6: E4 | J6: E4, E8 | K6: Média | L6: 23 | M6: Agrotóxicos, fiscalização e biossegurança | N6: Relaciona-se à fiscalização, biossegurança, fitossanidade e execução técnica em ambiente regulado. | O6: Priorizar monitoramento e avaliar nota técnica regulatória. | P6: Consolidada · abr/2026 | Q6: Proíbe a pulverização aérea de agrotóxicos em todo o território nacional, estabelece medidas de proteção à saúde humana, ao meio ambiente, aos recursos hídricos e às comunidades expostas, e dá outras providências. | R6: |E4|E8|
A7: PDL 4/2026 | B7: Câmara dos Deputados | C7: Projeto de decreto legislativo | D7: — | G7: 2026 | H7: 2026-02-02 | I7: E3 | J7: E3, E11, E12 | K7: Muito alta | L7: 22 | M7: Agrotóxicos, fiscalização e biossegurança | N7: Relaciona-se à fiscalização, biossegurança, fitossanidade e execução técnica em ambiente regulado. | O7: Priorizar monitoramento e avaliar nota técnica regulatória. | P7: Consolidada · abr/2026 | Q7: Susta a Instrução Normativa nº 125, de 23 de março de 2021, da Secretaria de Defesa Agropecuária do Ministério da Agricultura, Pecuária e Abastecimento, que atualiza os requisitos fitossanitários para a importação de amêndoas fermentadas e secas de cacau produzidas na Costa do Marfim. | R7: |E3|E11|E12|
A8: REQ 1/2026 | B8: Câmara dos Deputados | C8: Requerimento | D8: — | G8: 2026 | H8: 2026-02-05 | I8: E4 | J8: E4, E11, E12 | K8: Muito alta | L8: 22 | M8: Agrotóxicos, fiscalização e biossegurança | N8: Relaciona-se à fiscalização, biossegurança, fitossanidade e execução técnica em ambiente regulado. | O8: Priorizar monitoramento e avaliar nota técnica regulatória. | P8: Consolidada · abr/2026 | Q8: Requer a realização de audiência pública, no âmbito da Comissão de Agricultura, Pecuária, Abastecimento e Desenvolvimento Rural – CAPADR, para debater os impactos regulatórios, econômicos e concorrenciais da Portaria MAPA/SDA nº 805/2025, do Programa Nacional de Rastreabilidade de Produtos Agrotóxicos e Afins – PNRA, e da Portaria SDI/MAPA nº 739/2025, bem como da Instrução Normativa Conjunta SPA/SDI/SE-MAPA nº 001/2025, que tratam do credenciamento e da certificação obrigatória no setor de grãos. | R8: |E4|E11|E12|
A9: REQ 1285/2026 | B9: Câmara dos Deputados | C9: Requerimento | D9: — | G9: 2026 | H9: 2026-03-04 | I9: E3 | J9: E3, E11, E12 | K9: Muito alta | L9: 22 | M9: Agrotóxicos, fiscalização e biossegurança | N9: Relaciona-se à fiscalização, biossegurança, fitossanidade e execução técnica em ambiente regulado. | O9: Priorizar monitoramento e avaliar nota técnica regulatória. | P9: Consolidada · abr/2026 | Q9: Requer, nos termos do artigo 155 do Regimento Interno da Câmara dos Deputados, que seja incluído automaticamente na Ordem do Dia o PDL 330/2022, que “Susta a Instrução Normativa nº 125, de 23 de março de 2021, da Secretaria de Defesa Agropecuária do Ministério da Agricultura, Pecuária e Abastecimento, que atualiza os requisitos fitossanitários para a importação de amêndoas fermentadas e secas de cacau produzidas na Costa do Marfim”. | R9: |E3|E11|E12|
A10: REQ 44/2026 | B10: Câmara dos Deputados | C10: Requerimento | D10: — | G10: 2026 | H10: 2026-02-02 | I10: E3 | J10: E3, E11, E12 | K10: Muito alta | L10: 22 | M10: Agrotóxicos, fiscalização e biossegurança | N10: Relaciona-se à fiscalização, biossegurança, fitossanidade e execução técnica em ambiente regulado. | O10: Priorizar monitoramento e avaliar nota técnica regulatória. | P10: Consolidada · abr/2026 | Q10: Requer a inclusão do PDL 330/2022 que susta a Instrução Normativa nº 125, de 23 de março de 2021, da Secretaria de Defesa Agropecuária do Ministério da Agricultura, Pecuária e Abastecimento, que atualiza os requisitos fitossanitários para a importação de amêndoas fermentadas e secas de cacau produzidas na Costa do Marfim, na Ordem do Dia | R10: |E3|E11|E12|
A11: REQ 66/2026 | B11: Câmara dos Deputados | C11: Requerimento | D11: — | G11: 2026 | H11: 2026-02-02 | I11: E3 | J11: E3, E11, E12 | K11: Muito alta | L11: 22 | M11: Agrotóxicos, fiscalização e biossegurança | N11: Relaciona-se à fiscalização, biossegurança, fitossanidade e execução técnica em ambiente regulado. | O11: Priorizar monitoramento e avaliar nota técnica regulatória. | P11: Consolidada · abr/2026 | Q11: Requer urgência para o PDL 330/2022 que susta a Instrução Normativa nº 125, de 23 de março de 2021, da Secretaria de Defesa Agropecuária do Ministério da Agricultura, Pecuária e Abastecimento, que atualiza os requisitos fitossanitários para a importação de amêndoas fermentadas e secas de cacau produzidas na Costa do Marfim. | R11: |E3|E11|E12|
A12: PL 3692/2026 | B12: Câmara dos Deputados | C12: PL | D12: — | G12: 2026 | H12: 14/07/2026 | I12: E10 | J12: E10, E1 | K12: Muito alta | L12: 19 | P12: Varredura · ago/2026 | Q12: Institui o Estatuto Nacional dos Guias de Turismo, cria o Sistema Federal de Fiscalização da Profissão de Guia de Turismo – SIFGT, o Conselho Federal dos Guias de Turismo – CFGT e os Conselhos Regionais dos Guias de Turismo – CRGT, dispõe sobre o exercício da profissão de Guia de Turismo, altera a Lei nº 8.623, de 28 de janeiro de 1993. | R12: |E10|E1|
A13: PL 3933/2026 | B13: Câmara dos Deputados | C13: PL | D13: — | G13: 2026 | H13: 17/07/2026 | I13: E6 | J13: E6 | K13: Alta | L13: 19 | P13: Varredura · ago/2026 | Q13: Altera a Lei nº 14.119, de 13 de janeiro de 2021, para incluir as atividades de produção de sementes e mudas nativas destinadas à restauração ecológica entre as ações elegíveis para incentivos e pagamentos por serviços ambientais. | R13: |E6|
A14: INC 22/2026 | B14: Câmara dos Deputados | C14: Indicação | D14: — | G14: 2026 | H14: 2026-02-02 | I14: E3 | J14: E3, E12 | K14: Muito alta | L14: 17 | M14: Agrotóxicos, fiscalização e biossegurança | N14: Relaciona-se à fiscalização, biossegurança, fitossanidade e execução técnica em ambiente regulado. | O14: Priorizar monitoramento e avaliar nota técnica regulatória. | P14: Consolidada · abr/2026 | Q14: Sugere ao Ministério da Agricultura e Pecuária a revisão da Instrução Normativa nº 125, de 23 de março de 2021, da Secretaria de Defesa Agropecuária, que atualiza os requisitos fitossanitários para a importação de amêndoas fermentadas e secas de cacau produzidas na Costa do Marfim. | R14: |E3|E12|
A15: INC 381/2026 | B15: Câmara dos Deputados | C15: Indicação | D15: — | G15: 2026 | H15: 2026-03-19 | I15: E3 | J15: E3, E12 | K15: Muito alta | L15: 17 | M15: Agrotóxicos, fiscalização e biossegurança | N15: Relaciona-se à fiscalização, biossegurança, fitossanidade e execução técnica em ambiente regulado. | O15: Priorizar monitoramento e avaliar nota técnica regulatória. | P15: Consolidada · abr/2026 | Q15: Sugere ao Ministério da Agricultura e Pecuária a revisão da Instrução Normativa nº 125, de 23 de março de 2021, da Secretaria de Defesa Agropecuária, que atualiza os requisitos fitossanitários para a importação de amêndoas fermentadas e secas de cacau produzidas na Costa do Marfim. | R15: |E3|E12|
A16: PL 1389/2026 | B16: Senado Federal | C16: Projeto de lei | D16: Angelo Coronel | G16: 2026 | H16: 2026-03-24 | I16: E11 | J16: E11 | K16: Muito alta | L16: 17 | M16: Crédito rural, seguro e financiamento | N16: Pode alterar instrumentos de crédito ou financiamento relevantes para produtores rurais e para a assistência técnica. | O16: Monitorar tramitação e mapear impacto para produtores e assistência técnica. | P16: Consolidada · abr/2026 | Q16: Estabelece diretrizes para a aplicação de recursos do crédito rural e de instrumentos de gestão de risco no âmbito da política agrícola, com foco no semiárido brasileiro. | R16: |E11|
A17: PL 1393/2026 | B17: Senado Federal | C17: Projeto de lei | D17: Angelo Coronel | G17: 2026 | H17: 2026-03-24 | I17: E11 | J17: E11 | K17: Muito alta | L17: 17 | M17: Crédito rural, seguro e financiamento | N17: Pode alterar instrumentos de crédito ou financiamento relevantes para produtores rurais e para a assistência técnica. | O17: Monitorar tramitação e mapear impacto para produtores e assistência técnica. | P17: Consolidada · abr/2026 | Q17: Institui regime jurídico complementar de estabilização financeira aplicável às operações de crédito rural em situações de emergência decorrentes de eventos climáticos adversos no semiárido, em complemento aos instrumentos de gestão de risco da política agrícola. | R17: |E11|
A18: PL 4292/2026 | B18: Câmara dos Deputados | C18: PL | D18: — | G18: 2026 | H18: 17/07/2026 | I18: E11 | J18: E11, E7 | K18: Alta | L18: 17 | P18: Varredura · ago/2026 | Q18: Altera a Lei nº 8.629, de 25 de fevereiro de 1993, para estabelecer a obrigatoriedade de co-titularidade da mulher nos instrumentos de alienação, concessão, doação ou titulação de terras rurais e em contratos de crédito rural, dispondo sobre condições de preferência em programas públicos. | R18: |E11|E7|
